----------------------------------------
Exception occurred during processing of request from ('192.168.68.111', 52763)
Traceback (most recent call last):
  File "/usr/local/Cellar/python@3.13/3.13.3_1/Frameworks/Python.framework/Versions/3.13/lib/python3.13/socketserver.py", line 318, in _handle_request_noblock
    self.process_request(request, client_address)
    ~~~~~~~~~~~~~~~~~~~~^^^^^^^^^^^^^^^^^^^^^^^^^
  File "/usr/local/Cellar/python@3.13/3.13.3_1/Frameworks/Python.framework/Versions/3.13/lib/python3.13/socketserver.py", line 349, in process_request
    self.finish_request(request, client_address)
    ~~~~~~~~~~~~~~~~~~~^^^^^^^^^^^^^^^^^^^^^^^^^
  File "/usr/local/Cellar/python@3.13/3.13.3_1/Frameworks/Python.framework/Versions/3.13/lib/python3.13/socketserver.py", line 362, in finish_request
    self.RequestHandlerClass(request, client_address, self)
    ~~~~~~~~~~~~~~~~~~~~~~~~^^^^^^^^^^^^^^^^^^^^^^^^^^^^^^^
  File "/usr/local/Cellar/python@3.13/3.13.3_1/Frameworks/Python.framework/Versions/3.13/lib/python3.13/socketserver.py", line 766, in __init__
    self.handle()
    ~~~~~~~~~~~^^
  File "/usr/local/Cellar/python@3.13/3.13.3_1/Frameworks/Python.framework/Versions/3.13/lib/python3.13/http/server.py", line 436, in handle
    self.handle_one_request()
    ~~~~~~~~~~~~~~~~~~~~~~~^^
  File "/usr/local/Cellar/python@3.13/3.13.3_1/Frameworks/Python.framework/Versions/3.13/lib/python3.13/http/server.py", line 404, in handle_one_request
    self.raw_requestline = self.rfile.readline(65537)
                           ~~~~~~~~~~~~~~~~~~~^^^^^^^
  File "/usr/local/Cellar/python@3.13/3.13.3_1/Frameworks/Python.framework/Versions/3.13/lib/python3.13/socket.py", line 719, in readinto
    return self._sock.recv_into(b)
           ~~~~~~~~~~~~~~~~~~~~^^^
OSError: [Errno 57] Socket is not connected
----------------------------------------
----------------------------------------
Exception occurred during processing of request from ('192.168.68.111', 52766)
Traceback (most recent call last):
  File "/usr/local/Cellar/python@3.13/3.13.3_1/Frameworks/Python.framework/Versions/3.13/lib/python3.13/socketserver.py", line 318, in _handle_request_noblock
    self.process_request(request, client_address)
    ~~~~~~~~~~~~~~~~~~~~^^^^^^^^^^^^^^^^^^^^^^^^^
  File "/usr/local/Cellar/python@3.13/3.13.3_1/Frameworks/Python.framework/Versions/3.13/lib/python3.13/socketserver.py", line 349, in process_request
    self.finish_request(request, client_address)
    ~~~~~~~~~~~~~~~~~~~^^^^^^^^^^^^^^^^^^^^^^^^^
  File "/usr/local/Cellar/python@3.13/3.13.3_1/Frameworks/Python.framework/Versions/3.13/lib/python3.13/socketserver.py", line 362, in finish_request
    self.RequestHandlerClass(request, client_address, self)
    ~~~~~~~~~~~~~~~~~~~~~~~~^^^^^^^^^^^^^^^^^^^^^^^^^^^^^^^
  File "/usr/local/Cellar/python@3.13/3.13.3_1/Frameworks/Python.framework/Versions/3.13/lib/python3.13/socketserver.py", line 766, in __init__
    self.handle()
    ~~~~~~~~~~~^^
  File "/usr/local/Cellar/python@3.13/3.13.3_1/Frameworks/Python.framework/Versions/3.13/lib/python3.13/http/server.py", line 436, in handle
    self.handle_one_request()
    ~~~~~~~~~~~~~~~~~~~~~~~^^
  File "/usr/local/Cellar/python@3.13/3.13.3_1/Frameworks/Python.framework/Versions/3.13/lib/python3.13/http/server.py", line 404, in handle_one_request
    self.raw_requestline = self.rfile.readline(65537)
                           ~~~~~~~~~~~~~~~~~~~^^^^^^^
  File "/usr/local/Cellar/python@3.13/3.13.3_1/Frameworks/Python.framework/Versions/3.13/lib/python3.13/socket.py", line 719, in readinto
    return self._sock.recv_into(b)
           ~~~~~~~~~~~~~~~~~~~~^^^
OSError: [Errno 57] Socket is not connected
----------------------------------------
